<mujoco model="ur10e_robot">
  <compiler angle="radian" meshdir="meshes/flat" />
  <asset>
    <mesh name="base_vhacd" file="base_vhacd.obj" />
    <mesh name="shoulder_vhacd" file="shoulder_vhacd.obj" />
    <mesh name="upperarm_vhacd" file="upperarm_vhacd.obj" />
    <mesh name="forearm_vhacd" file="forearm_vhacd.obj" />
    <mesh name="wrist1_vhacd" file="wrist1_vhacd.obj" />
    <mesh name="wrist2_vhacd" file="wrist2_vhacd.obj" />
    <mesh name="wrist3_vhacd" file="wrist3_vhacd.obj" />
    <mesh name="base_link_vhacd" file="base_link_vhacd.obj" />
    <mesh name="left_outer_knuckle_vhacd" file="left_outer_knuckle_vhacd.obj" />
    <mesh name="left_inner_knuckle_vhacd" file="left_inner_knuckle_vhacd.obj" />
    <mesh name="left_inner_finger_vhacd" file="left_inner_finger_vhacd.obj" />
    <mesh name="outer_knuckle_vhacd" file="outer_knuckle_vhacd.obj" />
    <mesh name="inner_knuckle_vhacd" file="inner_knuckle_vhacd.obj" />
    <mesh name="inner_finger_vhacd" file="inner_finger_vhacd.obj" />
    <mesh name="airskin_0_vhacd" file="airskin_0_vhacd.obj" scale="0.001 0.001 0.001" />
    <mesh name="airskin_1_vhacd" file="airskin_1_vhacd.obj" scale="0.001 0.001 0.001" />
    <mesh name="airskin_2_vhacd" file="airskin_2_vhacd.obj" scale="0.001 0.001 0.001" />
    <mesh name="airskin_3_vhacd" file="airskin_3_vhacd.obj" scale="0.001 0.001 0.001" />
    <mesh name="airskin_4_vhacd" file="airskin_4_vhacd.obj" scale="0.001 0.001 0.001" />
    <mesh name="airskin_5_vhacd" file="airskin_5_vhacd.obj" scale="0.001 0.001 0.001" />
    <mesh name="airskin_6_vhacd" file="airskin_6_vhacd.obj" scale="0.001 0.001 0.001" />
    <mesh name="airskin_7_vhacd" file="airskin_7_vhacd.obj" scale="0.001 0.001 0.001" />
    <mesh name="airskin_8_vhacd" file="airskin_8_vhacd.obj" scale="0.001 0.001 0.001" />
    <mesh name="airskin_9_vhacd" file="airskin_9_vhacd.obj" scale="0.001 0.001 0.001" />
    <mesh name="airskin_10_vhacd" file="airskin_10_vhacd.obj" />
    <mesh name="airskin_11_vhacd" file="airskin_11_vhacd.obj" />
    <mesh name="table_vhacd" file="table_vhacd.obj" />
    <mesh name="base" file="base.obj" />
    <mesh name="shoulder" file="shoulder.obj" />
    <mesh name="upperarm" file="upperarm.obj" />
    <mesh name="forearm" file="forearm.obj" />
    <mesh name="wrist1" file="wrist1.obj" />
    <mesh name="wrist2" file="wrist2.obj" />
    <mesh name="wrist3" file="wrist3.obj" />
    <mesh name="base_link" file="base_link.obj" />
    <mesh name="left_outer_knuckle" file="left_outer_knuckle.obj" />
    <mesh name="left_inner_knuckle" file="left_inner_knuckle.obj" />
    <mesh name="left_inner_finger" file="left_inner_finger.obj" />
    <mesh name="outer_knuckle" file="outer_knuckle.obj" />
    <mesh name="inner_knuckle" file="inner_knuckle.obj" />
    <mesh name="inner_finger" file="inner_finger.obj" />
    <mesh name="table" file="table.obj" />
    <mesh name="airskin_0" file="airskin_0.obj" scale="0.001 0.001 0.001" />
    <mesh name="airskin_1" file="airskin_1.obj" scale="0.001 0.001 0.001" />
    <mesh name="airskin_2" file="airskin_2.obj" scale="0.001 0.001 0.001" />
    <mesh name="airskin_3" file="airskin_3.obj" scale="0.001 0.001 0.001" />
    <mesh name="airskin_4" file="airskin_4.obj" scale="0.001 0.001 0.001" />
    <mesh name="airskin_5" file="airskin_5.obj" scale="0.001 0.001 0.001" />
    <mesh name="airskin_6" file="airskin_6.obj" scale="0.001 0.001 0.001" />
    <mesh name="airskin_7" file="airskin_7.obj" scale="0.001 0.001 0.001" />
    <mesh name="airskin_8" file="airskin_8.obj" scale="0.001 0.001 0.001" />
    <mesh name="airskin_9" file="airskin_9.obj" scale="0.001 0.001 0.001" />
    <mesh name="airskin_10" file="airskin_10.obj" scale="0.001 0.001 0.001" />
    <mesh name="airskin_11" file="airskin_11.obj" scale="0.001 0.001 0.001" />
  </asset>
  <worldbody>
    <body name="base_mount" pos="0 0 0">
      <geom quat="-1 0 0 0" type="mesh" rgba="0.7 0.7 0.7 1" mesh="base_vhacd" />
      <geom quat="-1 0 0 0" type="mesh" mesh="base" contype="0" conaffinity="0" rgba="0.7 0.7 0.7 1" />
    </body>
    <geom pos="0.000430016 0.54 -0.0475" quat="0.707388 0 0 0.706825" type="mesh" rgba="1 0.7 0 1" mesh="table_vhacd" />
    <geom pos="0.000430016 0.54 -0.0475" quat="0.707388 0 0 0.706825" type="mesh" mesh="table" contype="0" conaffinity="0" rgba="1 0.7 0 1" />
    <body name="shoulder_link" pos="0 0 0.180988" quat="9.50488e-08 0 0 1">
      <inertial pos="0 0 0" mass="7.778" diaginertia="0.0314743 0.0314743 0.0218756" />
      <joint name="shoulder_pan_joint" pos="0 0 0" axis="0 0 1" range="-6.28319 6.28319" actuatorfrcrange="-330 330" />
      <geom quat="0 0 0 1" type="mesh" rgba="0.7 0.7 0.7 1" mesh="shoulder_vhacd" />
      <geom quat="0 0 0 1" type="mesh" mesh="shoulder" contype="0" conaffinity="0" rgba="0.7 0.7 0.7 1" />
      <body name="upper_arm_link" pos="0.000165471 0 0" quat="0.707225 0.706988 -1.39437e-06 -1.39484e-06">
        <inertial pos="-0.306004 0 0.175" quat="0.707107 0 0 0.707107" mass="12.934" diaginertia="0.421954 0.421758 0.0365657" />
        <joint name="shoulder_lift_joint" pos="0 0 0" axis="0 0 1" range="-6.28319 6.28319" actuatorfrcrange="-330 330" />
        <geom pos="0 0 0.1762" quat="0.5 0.5 -0.5 -0.5" type="mesh" rgba="0.7 0.7 0.7 1" mesh="upperarm_vhacd" />
        <geom pos="0 0 0.1762" quat="0.5 0.5 -0.5 -0.5" type="mesh" mesh="upperarm" contype="0" conaffinity="0" rgba="0.7 0.7 0.7 1" />
        <geom name="airskin_0_vhacd" pos="-0.03 0 0.185" quat="0.65427 0.268941 -0.653749 0.268727" type="mesh" rgba="0 0 1 1" mesh="airskin_0_vhacd" />
        <geom pos="-0.03 0 0.185" quat="0.65427 0.268941 -0.653749 0.268727" type="mesh" mesh="airskin_0" contype="0" conaffinity="0" rgba="0 0 1 1" />
        <geom name="airskin_1_vhacd" pos="-0.32 0.04 0.175032" quat="0.65427 0.268941 -0.653963 0.268206" type="mesh" rgba="0 0 1 1" mesh="airskin_1_vhacd" />
        <geom pos="-0.32 0.04 0.175032" quat="0.65427 0.268941 -0.653963 0.268206" type="mesh" mesh="airskin_1" contype="0" conaffinity="0" rgba="0 0 1 1" />
        <geom name="airskin_2_vhacd" pos="-0.32 -0.04 0.175032" quat="0.652917 0.272209 -0.65218 0.272512" type="mesh" rgba="0 0 1 1" mesh="airskin_2_vhacd" />
        <geom pos="-0.32 -0.04 0.175032" quat="0.652917 0.272209 -0.65218 0.272512" type="mesh" mesh="airskin_2" contype="0" conaffinity="0" rgba="0 0 1 1" />
        <geom name="airskin_3_vhacd" pos="-0.595 0 0.185" quat="0.65427 -0.268727 0.653749 0.268941" type="mesh" rgba="0 0 1 1" mesh="airskin_3_vhacd" />
        <geom pos="-0.595 0 0.185" quat="0.65427 -0.268727 0.653749 0.268941" type="mesh" mesh="airskin_3" contype="0" conaffinity="0" rgba="0 0 1 1" />
        <site name="airskin_0_site" pos="-0.03 0 0.185" quat="0.65427 0.268941 -0.653749 0.268727" size="0.05"/>
        <site name="airskin_1_site" pos="-0.32 0.04 0.175032" quat="0.65427 0.268941 -0.653963 0.268206" size="0.05"/>
        <site name="airskin_2_site" pos="-0.32 -0.04 0.175032" quat="0.652917 0.272209 -0.65218 0.272512" size="0.05"/>
        <site name="airskin_3_site" pos="-0.595 0 0.185" quat="0.65427 -0.268727 0.653749 0.268941" size="0.05"/>
        <body name="forearm_link" pos="-0.612321 0 0" quat="1 -0.000852766 -0.000134172 -9.42523e-08">
          <inertial pos="-0.285799 0 0.0393007" quat="0.707107 -7.17e-07 -7.17e-07 0.707107" mass="3.874" diaginertia="0.11096 0.110797 0.0110512" />
          <joint name="elbow_joint" pos="0 0 0" axis="0 0 1" range="-2.61799 2.61799" actuatorfrcrange="-150 150" />
          <geom pos="0 0 0.0393" quat="0.5 0.5 -0.5 -0.5" type="mesh" rgba="0.7 0.7 0.7 1" mesh="forearm_vhacd" />
          <geom pos="0 0 0.0393" quat="0.5 0.5 -0.5 -0.5" type="mesh" mesh="forearm" contype="0" conaffinity="0" rgba="0.7 0.7 0.7 1" />
          <geom name="airskin_4_vhacd" pos="-0.0199841 0.002 0.0299841" quat="-0.653228 0.268512 0.65479 0.269155" type="mesh" rgba="0 0 1 1" mesh="airskin_4_vhacd" />
          <geom pos="-0.0199841 0.002 0.0299841" quat="-0.653228 0.268512 0.65479 0.269155" type="mesh" mesh="airskin_4" contype="0" conaffinity="0" rgba="0 0 1 1" />
          <geom name="airskin_5_vhacd" pos="-0.29 0.0349944 0.0470279" quat="-0.26842 -0.654484 0.268727 -0.653749" type="mesh" rgba="0 0 1 1" mesh="airskin_5_vhacd" />
          <geom pos="-0.29 0.0349944 0.0470279" quat="-0.26842 -0.654484 0.268727 -0.653749" type="mesh" mesh="airskin_5" contype="0" conaffinity="0" rgba="0 0 1 1" />
          <geom name="airskin_6_vhacd" pos="-0.29 -0.0349944 0.0470279" quat="0.272729 0.6527 -0.271992 0.652397" type="mesh" rgba="0 0 1 1" mesh="airskin_6_vhacd" />
          <geom pos="-0.29 -0.0349944 0.0470279" quat="0.272729 0.6527 -0.271992 0.652397" type="mesh" mesh="airskin_6" contype="0" conaffinity="0" rgba="0 0 1 1" />
          <geom name="airskin_7_vhacd" pos="-0.545 0 0.0400478" quat="-0.653228 0.268512 0.65479 0.269155" type="mesh" rgba="0 0 1 1" mesh="airskin_7_vhacd" />
          <geom pos="-0.545 0 0.0400478" quat="-0.653228 0.268512 0.65479 0.269155" type="mesh" mesh="airskin_7" contype="0" conaffinity="0" rgba="0 0 1 1" />
          <site name="airskin_4_site" pos="-0.0199841 0.002 0.0299841" quat="-0.653228 0.268512 0.65479 0.269155" size="0.05"/>
          <site name="airskin_5_site" pos="-0.29 0.0349944 0.0470279" quat="-0.26842 -0.654484 0.268727 -0.653749" size="0.05"/>
          <site name="airskin_6_site" pos="-0.29 -0.0349944 0.0470279" quat="0.272729 0.6527 -0.271992 0.652397" size="0.05"/>
          <site name="airskin_7_site" pos="-0.545 0 0.0400478" quat="-0.653228 0.268512 0.65479 0.269155" size="0.05"/>
          <body name="wrist_1_link" pos="-0.57111 0.000600407 0.174603" quat="-0.999998 0.00171934 -0.000211748 -3.29292e-06">
            <inertial pos="0 0 0" quat="0.5 0.5 -0.5 0.5" mass="1.961" diaginertia="0.0055135 0.00510925 0.00510925" />
            <joint name="wrist_1_joint" pos="0 0 0" axis="0 0 1" range="-3.75246 0.610865" actuatorfrcrange="-56 56" />
            <geom pos="0 0 -0.135" quat="0.707107 0.707107 0 0" type="mesh" rgba="0.7 0.7 0.7 1" mesh="wrist1_vhacd" />
            <geom pos="0 0 -0.135" quat="0.707107 0.707107 0 0" type="mesh" mesh="wrist1" contype="0" conaffinity="0" rgba="0.7 0.7 0.7 1" />
            <geom name="airskin_8_vhacd" pos="0 0.01 7.96327e-06" quat="0.500398 0.5 -0.500398 0.499204" type="mesh" rgba="0 0 1 1" mesh="airskin_8_vhacd" />
            <geom pos="0 0.01 7.96327e-06" quat="0.500398 0.5 -0.500398 0.499204" type="mesh" mesh="airskin_8" contype="0" conaffinity="0" rgba="0 0 1 1" />
            <site name="airskin_8_site" pos="0 0.01 7.96327e-06" quat="0.500398 0.5 -0.500398 0.499204" size="0.05"/>
            <body name="wrist_2_link" pos="0.000112759 -0.119779 -1.79221e-05" quat="0.707054 0.70716 -1.00663e-06 -1.00648e-06">
              <inertial pos="0 0 0" quat="0.5 0.5 -0.5 0.5" mass="1.961" diaginertia="0.0055135 0.00510925 0.00510925" />
              <joint name="wrist_2_joint" pos="0 0 0" axis="0 0 1" range="-2.61799 2.70526" actuatorfrcrange="-56 56" />
              <geom pos="0 0 -0.12" quat="1 0 0 0" type="mesh" rgba="0.7 0.7 0.7 1" mesh="wrist2_vhacd" />
              <geom pos="0 0 -0.12" quat="1 0 0 0" type="mesh" mesh="wrist2" contype="0" conaffinity="0" rgba="0.7 0.7 0.7 1" />
              <geom name="airskin_9_vhacd" pos="0 -0.00999203 0.010008" quat="0.707388 0 0.000562864 0.706825" type="mesh" rgba="0 0 1 1" mesh="airskin_9_vhacd" />
              <geom pos="0 -0.00999203 0.010008" quat="0.707388 0 0.000562864 0.706825" type="mesh" mesh="airskin_9" contype="0" conaffinity="0" rgba="0 0 1 1" />
              <site name="airskin_9_site" pos="0 -0.00999203 0.010008" quat="0.707388 0 0.000562864 0.706825" size="0.05"/>
              <body name="wrist_3_link" pos="7.2501e-05 0.115643 -0.000116068" quat="0.706752 -0.707462 1.14899e-08 -1.14784e-08">
                <inertial pos="0 -2.70878e-05 -0.00497054" quat="0.949987 0.00567517 -0.00152051 -0.312234" mass="0.907" diaginertia="0.00136796 0.00136589 0.00121013" />
                <joint name="wrist_3_joint" pos="0 0 0" axis="0 0 1" range="-6.28319 5.23599" actuatorfrcrange="-56 56" />
                <geom pos="0 0 -0.1168" quat="0.707107 0.707107 0 0" type="mesh" rgba="0.7 0.7 0.7 1" mesh="wrist3_vhacd" />
                <geom pos="0 0 -0.1168" quat="0.707107 0.707107 0 0" type="mesh" mesh="wrist3" contype="0" conaffinity="0" rgba="0.7 0.7 0.7 1" />
                <geom quat="0.707107 -0.000281544 -0.000281544 -0.707107" type="mesh" rgba="0.8 0.8 0.8 1" mesh="base_link_vhacd" />
                <geom quat="0.707107 -0.000281544 -0.000281544 -0.707107" type="mesh" mesh="base_link" contype="0" conaffinity="0" rgba="0.8 0.8 0.8 1" />
                <geom name="airskin_10_vhacd" pos="0 -0.0249204 0.10002" quat="0.500398 0.499602 0.499602 -0.500398" type="mesh" rgba="0 0 1 1" mesh="airskin_10_vhacd" />
                <geom pos="0 -0.0249204 0.10002" quat="0.500398 0.499602 0.499602 -0.500398" type="mesh" mesh="airskin_10" contype="0" conaffinity="0" rgba="0 0 1 1" />
                <geom name="airskin_11_vhacd" pos="0 0.00021899 0.275" quat="0.707107 -0.000281544 -0.000281544 -0.707107" type="mesh" rgba="0 0 1 1" mesh="airskin_11_vhacd" />
                <geom pos="0 0.00021899 0.275" quat="0.707107 -0.000281544 -0.000281544 -0.707107" type="mesh" mesh="airskin_11" contype="0" conaffinity="0" rgba="0 0 1 1" />
                <site name="airskin_10_site" pos="0 -0.0249204 0.10002" quat="0.500398 0.499602 0.499602 -0.500398" size="0.05"/>
                <site name="airskin_11_site" pos="0 0.00021899 0.275" quat="0.707107 -0.000281544 -0.000281544 -0.707107" size="0.05"/>
                <body name="ee_tcp" pos="0 0.00016 0.2013">
                  <inertial pos="0 0 0" mass="0.001" diaginertia="1e-06 1e-06 1e-06"/>
                </body>
                <body name="jaws_link">
                  <inertial pos="0 0 0" mass="0.001" diaginertia="1e-06 1e-06 1e-06" />
                  <joint name="jaws_joint" pos="0 0 0" axis="0 0 1" type="slide" range="0 10" actuatorfrcrange="-1000 1000" />
                </body>
                <body name="left_outer_knuckle" pos="-0.024112 0.000108948 0.136813" quat="0.707107 -0.000281544 -0.000281544 -0.707107">
                  <inertial pos="0 0 0" quat="0.820473 0.339851 -0.17592 0.424708" mass="0.05" diaginertia="0.001002 0.000999 0.000999" />
                  <joint name="finger_joint" pos="0 0 0" axis="-1 0 0" range="-0.628319 0.628319" actuatorfrcrange="-1000 1000" />
                  <geom type="mesh" rgba="0.8 0.8 0.8 1" mesh="left_outer_knuckle_vhacd" />
                  <geom type="mesh" mesh="left_outer_knuckle" contype="0" conaffinity="0" rgba="0.8 0.8 0.8 1" />
                  <body name="left_inner_finger" pos="0 -0.047335 0.064495">
                    <inertial pos="0 0 0" quat="0.820473 0.339851 -0.17592 0.424708" mass="0.05" diaginertia="0.001002 0.000999 0.000999" />
                    <joint name="left_inner_finger_joint" pos="0 0 0" axis="1 0 0" range="-0.872665 0.872665" actuatorfrcrange="-1000 1000" />
                    <geom type="mesh" rgba="0.1 0.1 0.1 1" mesh="left_inner_finger_vhacd" />
                    <geom type="mesh" mesh="left_inner_finger" contype="0" conaffinity="0" rgba="0.1 0.1 0.1 1" />
                  </body>
                </body>
                <body name="left_inner_knuckle" pos="-0.01272 0.000127014 0.1595" quat="0.707107 -0.000281544 -0.000281544 -0.707107">
                  <inertial pos="0 0 0" quat="0.820473 0.339851 -0.17592 0.424708" mass="0.05" diaginertia="0.001002 0.000999 0.000999" />
                  <joint name="left_inner_knuckle_joint" pos="0 0 0" axis="1 0 0" range="-0.628319 0.628319" actuatorfrcrange="-1000 1000" />
                  <geom type="mesh" rgba="0.8 0.8 0.8 1" mesh="left_inner_knuckle_vhacd" />
                  <geom type="mesh" mesh="left_inner_knuckle" contype="0" conaffinity="0" rgba="0.8 0.8 0.8 1" />
                </body>
                <body name="right_outer_knuckle" pos="0.024112 0.000108948 0.136813" quat="0.707107 -0.000281544 0.000281544 0.707107">
                  <inertial pos="0 0 0" quat="0.820473 0.339851 -0.17592 0.424708" mass="0.05" diaginertia="0.001002 0.000999 0.000999" />
                  <joint name="right_outer_knuckle_joint" pos="0 0 0" axis="1 0 0" range="-0.628319 0.628319" actuatorfrcrange="-1000 1000" />
                  <geom type="mesh" rgba="0.8 0.8 0.8 1" mesh="outer_knuckle_vhacd" />
                  <geom type="mesh" mesh="outer_knuckle" contype="0" conaffinity="0" rgba="0.8 0.8 0.8 1" />
                  <body name="right_inner_finger" pos="0 -0.047335 0.064495">
                    <inertial pos="0 0 0" quat="0.820473 0.339851 -0.17592 0.424708" mass="0.05" diaginertia="0.001002 0.000999 0.000999" />
                    <joint name="right_inner_finger_joint" pos="0 0 0" axis="1 0 0" range="-0.872665 0.872665" actuatorfrcrange="-1000 1000" />
                    <geom type="mesh" rgba="0.1 0.1 0.1 1" mesh="inner_finger_vhacd" />
                    <geom type="mesh" mesh="inner_finger" contype="0" conaffinity="0" rgba="0.1 0.1 0.1 1" />
                  </body>
                </body>
                <body name="right_inner_knuckle" pos="0.01272 0.000127014 0.1595" quat="-0.707107 0.000281544 -0.000281544 -0.707107">
                  <inertial pos="0 0 0" quat="0.820473 0.339851 -0.17592 0.424708" mass="0.05" diaginertia="0.001002 0.000999 0.000999" />
                  <joint name="right_inner_knuckle_joint" pos="0 0 0" axis="1 0 0" range="-0.628319 0.628319" actuatorfrcrange="-1000 1000" />
                  <geom type="mesh" rgba="0.8 0.8 0.8 1" mesh="inner_knuckle_vhacd" />
                  <geom type="mesh" mesh="inner_knuckle" contype="0" conaffinity="0" rgba="0.8 0.8 0.8 1" />
                </body>
              </body>
            </body>
          </body>
        </body>
      </body>
    </body>
  </worldbody>
  <contact>
    <exclude body1="base_mount" body2="shoulder_link" />
    <exclude body1="left_inner_finger" body2="left_inner_knuckle" />
    <exclude body1="right_inner_finger" body2="right_inner_knuckle" />
  </contact>
  <sensor>
    <touch name="airskin_0"  site="airskin_0_site"/>
    <touch name="airskin_1"  site="airskin_1_site"/>
    <touch name="airskin_2"  site="airskin_2_site"/>
    <touch name="airskin_3"  site="airskin_3_site"/>
    <touch name="airskin_4"  site="airskin_4_site"/>
    <touch name="airskin_5"  site="airskin_5_site"/>
    <touch name="airskin_6"  site="airskin_6_site"/>
    <touch name="airskin_7"  site="airskin_7_site"/>
    <touch name="airskin_8"  site="airskin_8_site"/>
    <touch name="airskin_9"  site="airskin_9_site"/>
    <touch name="airskin_10" site="airskin_10_site"/>
    <touch name="airskin_11" site="airskin_11_site"/>
  </sensor>
  <actuator>
    <motor name="act_shoulder_pan"  joint="shoulder_pan_joint"  gear="1" forcerange="-330 330"  ctrlrange="-330 330"/>
    <motor name="act_shoulder_lift" joint="shoulder_lift_joint" gear="1" forcerange="-330 330"  ctrlrange="-330 330"/>
    <motor name="act_elbow"         joint="elbow_joint"         gear="1" forcerange="-150 150"  ctrlrange="-150 150"/>
    <motor name="act_wrist_1"       joint="wrist_1_joint"       gear="1" forcerange="-56 56"    ctrlrange="-56 56"/>
    <motor name="act_wrist_2"       joint="wrist_2_joint"       gear="1" forcerange="-56 56"    ctrlrange="-56 56"/>
    <motor    name="act_wrist_3"             joint="wrist_3_joint"             gear="1" forcerange="-56 56"   ctrlrange="-56 56"/>
    <position name="act_finger"              joint="finger_joint"              kp="100" ctrlrange="-0.628 0.628"/>
    <position name="act_left_inner_finger"   joint="left_inner_finger_joint"   kp="100" ctrlrange="-0.872 0.872"/>
    <position name="act_left_inner_knuckle"  joint="left_inner_knuckle_joint"  kp="100" ctrlrange="-0.628 0.628"/>
    <position name="act_right_outer_knuckle" joint="right_outer_knuckle_joint" kp="100" ctrlrange="-0.628 0.628"/>
    <position name="act_right_inner_finger"  joint="right_inner_finger_joint"  kp="100" ctrlrange="-0.872 0.872"/>
    <position name="act_right_inner_knuckle" joint="right_inner_knuckle_joint" kp="100" ctrlrange="-0.628 0.628"/>
  </actuator>
</mujoco>
